<?xml version="1.0"?>
<robot xmlns:xacro="http://www.ros.org/wiki/xacro">

    <link name="base_link"></link>

    <joint name="chassis_joint" type="fixed">
        <parent link="base_link"/>
        <child link="chassis"/>
        <origin xyz="-0.1 0 0"/>
    </joint>
    <link name="chassis">
        <collision>
            <origin xyz="0.0935 0 0.00" rpy="0 0 0"/>
            <geometry>
                <box size="0.187 0.095 0.04"/>
            </geometry>
        </collision>
        <visual>
            <origin xyz="0.0935 0 0.00" rpy="0 0 0"/>
            <geometry>
                <box size="0.187 0.095 0.04"/>
            </geometry>
            <material name="white"/>
        </visual>
        <xacro:inertial_box mass="0.5" x="0.187" y="0.095" z="0.04">
            <origin xyz="0.0935 0 0.04675" rpy="0 0 0"/>
        </xacro:inertial_box>
    </link>

    <!-- Front Left Wheel -->
    <joint name="front_left_wheel_joint" type="continuous">
        <parent link="base_link"/>
        <child link="front_left_wheel"/>
        <origin xyz="-0.0585 0.0725 0" rpy="-${pi/2} 0 0"/>
        <axis xyz="0 0 1"/>
        <limit effort="100.0" lower="-100" upper="100" velocity="1"/>
    </joint>
    <link name="front_left_wheel">
        <collision>
            <geometry>
                <cylinder length="0.03" radius="0.0325" />
            </geometry>
        </collision>
        <visual>
            <geometry>
                <cylinder length="0.03" radius="0.0325" />
            </geometry>
            <material name="yellow"/>
        </visual>
        <xacro:inertial_cylinder mass="0.1" length="0.03" radius="0.0325">
            <origin xyz="0 0 0" rpy="0 0 0"/>
        </xacro:inertial_cylinder>
    </link>

    <!-- Front Right Wheel -->
    <joint name="front_right_wheel_joint" type="continuous">
        <parent link="base_link"/>
        <child link="front_right_wheel"/>
        <origin xyz="-0.0585 -0.0725 0" rpy="${pi/2} 0 0"/>
        <axis xyz="0 0 -1"/>
        <limit effort="100.0" lower="-100" upper="100" velocity="1"/>
    </joint>
    <link name="front_right_wheel">
        <collision>
            <geometry>
                <cylinder length="0.03" radius="0.0325" />
            </geometry>
        </collision>
        <visual>
            <geometry>
                <cylinder length="0.03" radius="0.0325" />
            </geometry>
            <material name="yellow"/>
        </visual>
        <xacro:inertial_cylinder mass="0.1" length="0.03" radius="0.0325">
            <origin xyz="0 0 0" rpy="0 0 0"/>
        </xacro:inertial_cylinder>
    </link>

    <!-- Rear Left Wheel -->
    <joint name="rear_left_wheel_joint" type="continuous">
        <parent link="base_link"/>
        <child link="rear_left_wheel"/>
        <origin xyz="0.062 0.0725 0" rpy="-${pi/2} 0 0"/>
        <axis xyz="0 0 1"/>
        <limit effort="100.0" lower="-100" upper="100" velocity="1"/>
    </joint>
    <link name="rear_left_wheel">
        <collision>
            <geometry>
                <cylinder length="0.03" radius="0.0325" />
            </geometry>
        </collision>
        <visual>
            <geometry>
                <cylinder length="0.03" radius="0.0325" />
            </geometry>
            <material name="yellow"/>
        </visual>
        <xacro:inertial_cylinder mass="0.1" length="0.03" radius="0.0325">
            <origin xyz="0 0 0" rpy="0 0 0"/>
        </xacro:inertial_cylinder>
    </link>

    <!-- Rear Right Wheel -->
    <joint name="rear_right_wheel_joint" type="continuous">
        <parent link="base_link"/>
        <child link="rear_right_wheel"/>
        <origin xyz="0.062 -0.0725 0" rpy="${pi/2} 0 0"/>
        <axis xyz="0 0 -1"/>
        <limit effort="100.0" lower="-100" upper="100" velocity="1"/>
    </joint>
    <link name="rear_right_wheel">
        <collision>
            <geometry>
                <cylinder length="0.03" radius="0.0325" />
            </geometry>
        </collision>
        <visual>
            <geometry>
                <cylinder length="0.03" radius="0.0325" />
            </geometry>
            <material name="yellow"/>
        </visual>
        <xacro:inertial_cylinder mass="0.1" length="0.03" radius="0.0325">
            <origin xyz="0 0 0" rpy="0 0 0"/>
        </xacro:inertial_cylinder>
    </link>

</robot>
